<?xml version="1.0"?>
<robot name="wheeled_robot" xmlns:xacro="http://www.ros.org/wiki/xacro">
  <!-- Base Link -->
  <link name="chassis">
    <collision>
      <geometry>
        <box size="2 1 0.5"/>
      </geometry>
    </collision>
    <visual>
      <geometry>
        <box size="2 1 0.5"/>
      </geometry>
      <material name="blue">
        <color rgba="0 0 1 1.0"/>
      </material>
    </visual>
    <inertial>
      <mass value="1.14395"/>
      <inertia
        ixx="0.126164" ixy="0.0" ixz="0.0"
        iyy="0.416519" iyz="0.0"
        izz="0.481014"/>
    </inertial>
  </link>

  <link name="lidar_frame">
    <collision>
      <geometry>
        <cylinder radius="0.05" length="0.2"/>
      </geometry>
    </collision>
    <visual>
      <geometry>
        <cylinder radius="0.05" length="0.2"/>
      </geometry>
      <material name="red">
        <color rgba="1.0 0 0 1.0"/>
      </material>
    </visual>
  </link>
  <joint name="lidar_joint" type="fixed">
    <parent link="chassis"/>
    <child link="lidar_frame"/>
    <origin xyz="0 0 0.5" rpy="0 0 0"/>
    <axis xyz="0 0 1"/>
  </joint>

  <link name="front_left_wheel">
    <collision>
      <geometry>
        <cylinder radius="0.4" length="0.2"/>
      </geometry>
    </collision>
    <visual>
      <geometry>
        <cylinder radius="0.4" length="0.2"/>
      </geometry>
      <material name="red">
        <color rgba="1 0 0 1.0"/>
      </material>
    </visual>
    <inertial>
      <mass value="2"/>
      <inertia
        ixx="0.145833" ixy="0.0" ixz="0.0"
        iyy="0.145833" iyz="0.0"
        izz="0.125"/>
    </inertial>
  </link>
  <joint name="front_left_wheel_joint" type="continuous">
    <parent link="front_left_wheel_steering"/>
    <child link="front_left_wheel"/>
    <origin xyz="0 0 0" rpy="-1.5707 0 0"/>
    <axis xyz="0 0 1"/>
  </joint>

  <link name="front_left_wheel_steering">
      <inertial>
      <mass value="2"/>
      <inertia
        ixx="0.145833" ixy="0.0" ixz="0.0"
        iyy="0.145833" iyz="0.0"
        izz="0.125"/>
    </inertial>
  </link>
  <joint name="front_left_wheel_steering_joint" type="continuous">
    <parent link="chassis"/>
    <child link="front_left_wheel_steering"/>
    <origin xyz="0.5 0.6 0" rpy="0 0 0"/>
    <axis xyz="0 0 1"/>
  </joint>

  <link name="front_right_wheel">
    <collision>
      <geometry>
        <cylinder radius="0.4" length="0.2"/>
      </geometry>
    </collision>
    <visual>
      <geometry>
        <cylinder radius="0.4" length="0.2"/>
      </geometry>
      <material name="red">
        <color rgba="1 0 0 1.0"/>
      </material>
    </visual>
    <inertial>
      <mass value="2"/>
      <inertia
        ixx="0.145833" ixy="0.0" ixz="0.0"
        iyy="0.145833" iyz="0.0"
        izz="0.125"/>
    </inertial>
  </link>
  <joint name="front_right_wheel_joint" type="continuous">
    <parent link="front_right_wheel_steering"/>
    <child link="front_right_wheel"/>
    <origin xyz="0 0 0" rpy="-1.5707 0 0"/>
    <axis xyz="0 0 1"/>
  </joint>

  <link name="front_right_wheel_steering">
    <inertial>
      <mass value="2"/>
      <inertia
        ixx="0.145833" ixy="0.0" ixz="0.0"
        iyy="0.145833" iyz="0.0"
        izz="0.125"/>
    </inertial>
  </link>
  <joint name="front_right_wheel_steering_joint" type="continuous">
    <parent link="chassis"/>
    <child link="front_right_wheel_steering"/>
    <origin xyz="0.5 -0.6 0" rpy="0 0 0"/>
    <axis xyz="0 0 1"/>
  </joint>

  <link name="back_left_wheel">
    <collision>
      <geometry>
        <cylinder radius="0.4" length="0.2"/>
      </geometry>
    </collision>
    <visual>
      <geometry>
        <cylinder radius="0.4" length="0.2"/>
      </geometry>
      <material name="red">
        <color rgba="1 0 0 1.0"/>
      </material>
    </visual>
    <inertial>
      <mass value="2"/>
      <inertia
        ixx="0.145833" ixy="0.0" ixz="0.0"
        iyy="0.145833" iyz="0.0"
        izz="0.125"/>
    </inertial>
  </link>
  <joint name="back_left_wheel_joint" type="continuous">
    <parent link="chassis"/>
    <child link="back_left_wheel"/>
    <origin xyz="-0.5 0.6 0" rpy="-1.5707 0 0"/>
    <axis xyz="0 0 1"/>
  </joint>

  <link name="back_right_wheel">
    <collision>
      <geometry>
        <cylinder radius="0.4" length="0.2"/>
      </geometry>
    </collision>
    <visual>
      <geometry>
        <cylinder radius="0.4" length="0.2"/>
      </geometry>
      <material name="red">
        <color rgba="1 0 0 1.0"/>
      </material>
    </visual>
    <inertial>
      <mass value="2"/>
      <inertia
        ixx="0.145833" ixy="0.0" ixz="0.0"
        iyy="0.145833" iyz="0.0"
        izz="0.125"/>
    </inertial>
  </link>
  <joint name="back_right_wheel_joint" type="continuous">
    <parent link="chassis"/>
    <child link="back_right_wheel"/>
    <origin xyz="-0.5 -0.6 0" rpy="-1.5707 0 0"/>
    <axis xyz="0 0 1"/>
  </joint>

  <gazebo reference="lidar_frame">
    <sensor name="lidar" type="ray">
      <pose relative_to='lidar_frame'>0 0 0 0 0 0</pose>
      <visualize>true</visualize>
      <update_rate>10</update_rate>
      <ray> 
              <scan>
                  <horizontal>
                      <samples>360</samples>
                      <min_angle>-3.14</min_angle>
                      <max_angle>3.14</max_angle>
                  </horizontal>
              </scan>
              <range>
                  <min>0.3</min>
                  <max>12</max>
              </range>
      </ray>
      <plugin name="laser_controller" filename="libgazebo_ros_ray_sensor.so">
          <ros>
              <remapping>~/out:=scan</remapping>
          </ros>
          <output_type>sensor_msgs/LaserScan</output_type>
          <frame_name>lidar_frame</frame_name>
      </plugin>
    </sensor>

  </gazebo>

  <gazebo>
          <plugin name="wheeled_robot_joint_state" filename="libgazebo_ros_joint_state_publisher.so">
          <ros>
              <remapping>~/out:=joint_states</remapping>
          </ros>
          <update_rate>30</update_rate>
          <joint_name>front_right_wheel_joint</joint_name>
          <joint_name>front_left_wheel_joint</joint_name>
          <joint_name>back_right_wheel_joint</joint_name>
          <joint_name>back_left_wheel_joint</joint_name>
          <joint_name>front_right_wheel_steering_joint</joint_name>
          <joint_name>front_left_wheel_steering_joint</joint_name>
        </plugin>
  </gazebo>


    <ros2_control name="GazeboSystem" type="system">
      <hardware>
        <plugin>gazebo_ros2_control/GazeboSystem</plugin>
      </hardware>
      
      <joint name="front_right_wheel_joint">
        <command_interface name="velocity">
          <param name="min">-3.14</param>
          <param name="max">3.14</param>
        </command_interface>
        <state_interface name="velocity"/>
        <state_interface name="effort"/>
      </joint>

      <joint name="front_left_wheel_joint">
        <command_interface name="velocity">
          <param name="min">-3.14</param>
          <param name="max">3.14</param>
        </command_interface>
        <state_interface name="velocity"/>
        <state_interface name="effort"/>
      </joint>

      <joint name="back_right_wheel_joint">
        <command_interface name="velocity">
          <param name="min">-3.14</param>
          <param name="max">3.14</param>
        </command_interface>
        <state_interface name="velocity"/>
        <state_interface name="effort"/>
      </joint>

      <joint name="back_left_wheel_joint">
        <command_interface name="velocity">
          <param name="min">-3.14</param>
          <param name="max">3.14</param>
        </command_interface>
        <state_interface name="velocity"/>
        <state_interface name="effort"/>
      </joint>

      <joint name="front_right_wheel_steering_joint">
        <command_interface name="position">
          <param name="min">-3.14</param>
          <param name="max">3.14</param>
        </command_interface>
        <state_interface name="position">
          <param name="initial_value">0</param>
        </state_interface>
        <state_interface name="velocity"/>
        <state_interface name="effort"/>
      </joint>

      <joint name="front_left_wheel_steering_joint">
        <command_interface name="position">
          <param name="min">-3.14</param>
          <param name="max">3.14</param>
        </command_interface>
        <state_interface name="position">
          <param name="initial_value">0</param>
        </state_interface>
        <state_interface name="velocity"/>
        <state_interface name="effort"/>
      </joint>

    </ros2_control>

  <gazebo>
    <plugin name="gazebo_ros2_control" filename="libgazebo_ros2_control.so">
      <parameters>/home/radu/four_ws_vehicle/ws/install/four_ws_vehicle_simulation/share/four_ws_vehicle_simulation/models/config/controllers.yaml</parameters>
    </plugin>
  </gazebo>

</robot>